Input Notebook:  /data/aglinska/BC-fMRI-AE/Notebooks/014-SFARI-compcorr-filter.ipynb
Output Notebook: /data/aglinska/BC-fMRI-AE/Assets/papermill-SFARI-preproc/189-run2-sfari-compcorr.ipynb
Generating grammar tables from /data/aglinska/anaconda3/lib/python3.8/site-packages/blib2to3/Grammar.txt
Writing grammar tables to /data/aglinska/.cache/black/21.8b0/Grammar3.8.5.final.0.pickle
Writing failed: [Errno 2] No such file or directory: '/data/aglinska/.cache/black/21.8b0/tmpnia7cx2s'
Generating grammar tables from /data/aglinska/anaconda3/lib/python3.8/site-packages/blib2to3/PatternGrammar.txt
Writing grammar tables to /data/aglinska/.cache/black/21.8b0/PatternGrammar3.8.5.final.0.pickle
Writing failed: [Errno 2] No such file or directory: '/data/aglinska/.cache/black/21.8b0/tmpzhk0dhuw'
Executing:   0%|          | 0/36 [00:00<?, ?cell/s]Executing notebook with kernel: python3
Executing:   3%|▎         | 1/36 [00:01<01:08,  1.95s/cell]Executing:  11%|█         | 4/36 [00:02<00:44,  1.38s/cell]Executing:  14%|█▍        | 5/36 [00:09<01:41,  3.29s/cell]Executing:  22%|██▏       | 8/36 [00:10<01:05,  2.35s/cell]Executing:  28%|██▊       | 10/36 [00:10<00:43,  1.67s/cell]Executing:  33%|███▎      | 12/36 [00:10<00:28,  1.19s/cell]Executing:  39%|███▉      | 14/36 [00:10<00:18,  1.16cell/s]Executing:  44%|████▍     | 16/36 [00:12<00:17,  1.12cell/s]Executing:  44%|████▍     | 16/36 [00:14<00:18,  1.08cell/s]
Traceback (most recent call last):
  File "/data/aglinska/anaconda3/bin/papermill", line 8, in <module>
    sys.exit(papermill())
  File "/data/aglinska/anaconda3/lib/python3.8/site-packages/click/core.py", line 829, in __call__
    return self.main(*args, **kwargs)
  File "/data/aglinska/anaconda3/lib/python3.8/site-packages/click/core.py", line 782, in main
    rv = self.invoke(ctx)
  File "/data/aglinska/anaconda3/lib/python3.8/site-packages/click/core.py", line 1066, in invoke
    return ctx.invoke(self.callback, **ctx.params)
  File "/data/aglinska/anaconda3/lib/python3.8/site-packages/click/core.py", line 610, in invoke
    return callback(*args, **kwargs)
  File "/data/aglinska/anaconda3/lib/python3.8/site-packages/click/decorators.py", line 21, in new_func
    return f(get_current_context(), *args, **kwargs)
  File "/data/aglinska/anaconda3/lib/python3.8/site-packages/papermill/cli.py", line 250, in papermill
    execute_notebook(
  File "/data/aglinska/anaconda3/lib/python3.8/site-packages/papermill/execute.py", line 122, in execute_notebook
    raise_for_execution_errors(nb, output_path)
  File "/data/aglinska/anaconda3/lib/python3.8/site-packages/papermill/execute.py", line 234, in raise_for_execution_errors
    raise error
papermill.exceptions.PapermillExecutionError: 
---------------------------------------------------------------------------
Exception encountered at "In [16]":
---------------------------------------------------------------------------
IndexError                                Traceback (most recent call last)
<ipython-input-16-6b2831697ab1> in <module>
----> 1 sub = subjects[s]
      2 print(sub)
      3 data = get_data(sub)
      4 n = data['epi'].shape[-1]
      5 print(data['epi'].shape)

IndexError: index 189 is out of bounds for axis 0 with size 189

