Input Notebook:  /data/aglinska/BC-fMRI-AE/Notebooks/004-SFARI-compcorr-filter.ipynb
Output Notebook: /data/aglinska/BC-fMRI-AE/Assets/data_preprocessed_sfari-run1_notebooks/139-run2-sfari-compcorr.ipynb
Generating grammar tables from /data/aglinska/anaconda3/lib/python3.8/site-packages/blib2to3/Grammar.txt
Writing grammar tables to /data/aglinska/.cache/black/21.8b0/Grammar3.8.5.final.0.pickle
Writing failed: [Errno 2] No such file or directory: '/data/aglinska/.cache/black/21.8b0/tmp4cavrlr0'
Generating grammar tables from /data/aglinska/anaconda3/lib/python3.8/site-packages/blib2to3/PatternGrammar.txt
Writing grammar tables to /data/aglinska/.cache/black/21.8b0/PatternGrammar3.8.5.final.0.pickle
Writing failed: [Errno 2] No such file or directory: '/data/aglinska/.cache/black/21.8b0/tmpu480tnmv'
Executing:   0%|          | 0/70 [00:00<?, ?cell/s]Executing notebook with kernel: python3
Executing:   1%|▏         | 1/70 [00:06<07:03,  6.14s/cell]Executing:   4%|▍         | 3/70 [00:42<10:54,  9.77s/cell]Executing:   7%|▋         | 5/70 [00:42<07:25,  6.85s/cell]Executing:  10%|█         | 7/70 [00:43<05:13,  4.98s/cell]Executing:  13%|█▎        | 9/70 [00:44<03:33,  3.50s/cell]Executing:  16%|█▌        | 11/70 [00:44<02:25,  2.47s/cell]Executing:  19%|█▊        | 13/70 [00:44<01:39,  1.75s/cell]Executing:  21%|██▏       | 15/70 [00:44<01:08,  1.24s/cell]Executing:  24%|██▍       | 17/70 [00:48<01:21,  1.55s/cell]Executing:  27%|██▋       | 19/70 [00:49<00:55,  1.10s/cell]Executing:  30%|███       | 21/70 [00:49<00:38,  1.27cell/s]Executing:  33%|███▎      | 23/70 [00:49<00:26,  1.76cell/s]Executing:  36%|███▌      | 25/70 [00:49<00:18,  2.41cell/s]Executing:  39%|███▊      | 27/70 [00:49<00:13,  3.26cell/s]Executing:  41%|████▏     | 29/70 [00:49<00:11,  3.44cell/s]Executing:  44%|████▍     | 31/70 [00:50<00:09,  4.19cell/s]Executing:  47%|████▋     | 33/70 [00:54<00:30,  1.21cell/s]Executing:  47%|████▋     | 33/70 [00:57<01:04,  1.75s/cell]
Traceback (most recent call last):
  File "/data/aglinska/anaconda3/bin/papermill", line 8, in <module>
    sys.exit(papermill())
  File "/data/aglinska/anaconda3/lib/python3.8/site-packages/click/core.py", line 829, in __call__
    return self.main(*args, **kwargs)
  File "/data/aglinska/anaconda3/lib/python3.8/site-packages/click/core.py", line 782, in main
    rv = self.invoke(ctx)
  File "/data/aglinska/anaconda3/lib/python3.8/site-packages/click/core.py", line 1066, in invoke
    return ctx.invoke(self.callback, **ctx.params)
  File "/data/aglinska/anaconda3/lib/python3.8/site-packages/click/core.py", line 610, in invoke
    return callback(*args, **kwargs)
  File "/data/aglinska/anaconda3/lib/python3.8/site-packages/click/decorators.py", line 21, in new_func
    return f(get_current_context(), *args, **kwargs)
  File "/data/aglinska/anaconda3/lib/python3.8/site-packages/papermill/cli.py", line 250, in papermill
    execute_notebook(
  File "/data/aglinska/anaconda3/lib/python3.8/site-packages/papermill/execute.py", line 122, in execute_notebook
    raise_for_execution_errors(nb, output_path)
  File "/data/aglinska/anaconda3/lib/python3.8/site-packages/papermill/execute.py", line 234, in raise_for_execution_errors
    raise error
papermill.exceptions.PapermillExecutionError: 
---------------------------------------------------------------------------
Exception encountered at "In [24]":
---------------------------------------------------------------------------
KeyError                                  Traceback (most recent call last)
<ipython-input-24-14dc412227e8> in <module>
     10 scrubbed_nii = make_4depi(mat,data['epi'])
     11 
---> 12 rmat = regress(mat,data['conf'].iloc[~scrub_idx])
     13 
     14 rmat_nii = make_4depi(rmat,data['epi'])

<ipython-input-14-92b9476e4852> in regress(flat_epi, conf, idx)
     20 
     21 
---> 22     X = conf[keys].values[idx]
     23     n = X.shape[0]
     24     X = np.hstack((X,np.ones(n)[:,np.newaxis])) # Add mean

~/anaconda3/lib/python3.8/site-packages/pandas/core/frame.py in __getitem__(self, key)
   2906             if is_iterator(key):
   2907                 key = list(key)
-> 2908             indexer = self.loc._get_listlike_indexer(key, axis=1, raise_missing=True)[1]
   2909 
   2910         # take() does not accept boolean indexers

~/anaconda3/lib/python3.8/site-packages/pandas/core/indexing.py in _get_listlike_indexer(self, key, axis, raise_missing)
   1252             keyarr, indexer, new_indexer = ax._reindex_non_unique(keyarr)
   1253 
-> 1254         self._validate_read_indexer(keyarr, indexer, axis, raise_missing=raise_missing)
   1255         return keyarr, indexer
   1256 

~/anaconda3/lib/python3.8/site-packages/pandas/core/indexing.py in _validate_read_indexer(self, key, indexer, axis, raise_missing)
   1302             if raise_missing:
   1303                 not_found = list(set(key) - set(ax))
-> 1304                 raise KeyError(f"{not_found} not in index")
   1305 
   1306             # we skip the warning on Categorical

KeyError: "['a_comp_cor_04', 'a_comp_cor_03', 'a_comp_cor_00', 'a_comp_cor_01', 'a_comp_cor_02'] not in index"

