Input Notebook:  /data/aglinska/BC-fMRI-AE/Notebooks/014-SFARI-compcorr-filter.ipynb
Output Notebook: /data/aglinska/BC-fMRI-AE/Assets/papermill-SFARI-preproc/191-run2-sfari-compcorr.ipynb
Generating grammar tables from /data/aglinska/anaconda3/lib/python3.8/site-packages/blib2to3/Grammar.txt
Writing grammar tables to /data/aglinska/.cache/black/21.8b0/Grammar3.8.5.final.0.pickle
Writing failed: [Errno 2] No such file or directory: '/data/aglinska/.cache/black/21.8b0/tmpuugd1cb6'
Generating grammar tables from /data/aglinska/anaconda3/lib/python3.8/site-packages/blib2to3/PatternGrammar.txt
Writing grammar tables to /data/aglinska/.cache/black/21.8b0/PatternGrammar3.8.5.final.0.pickle
Writing failed: [Errno 2] No such file or directory: '/data/aglinska/.cache/black/21.8b0/tmpidonoplv'
Executing:   0%|          | 0/36 [00:00<?, ?cell/s]Executing notebook with kernel: python3
Executing:   3%|▎         | 1/36 [00:02<01:22,  2.37s/cell]Executing:   8%|▊         | 3/36 [00:02<00:55,  1.69s/cell]Executing:  14%|█▍        | 5/36 [00:09<01:10,  2.26s/cell]Executing:  22%|██▏       | 8/36 [00:10<00:45,  1.64s/cell]Executing:  31%|███       | 11/36 [00:10<00:28,  1.16s/cell]Executing:  39%|███▉      | 14/36 [00:10<00:18,  1.21cell/s]Executing:  44%|████▍     | 16/36 [00:12<00:16,  1.20cell/s]Executing:  44%|████▍     | 16/36 [00:13<00:17,  1.14cell/s]
Traceback (most recent call last):
  File "/data/aglinska/anaconda3/bin/papermill", line 8, in <module>
    sys.exit(papermill())
  File "/data/aglinska/anaconda3/lib/python3.8/site-packages/click/core.py", line 829, in __call__
    return self.main(*args, **kwargs)
  File "/data/aglinska/anaconda3/lib/python3.8/site-packages/click/core.py", line 782, in main
    rv = self.invoke(ctx)
  File "/data/aglinska/anaconda3/lib/python3.8/site-packages/click/core.py", line 1066, in invoke
    return ctx.invoke(self.callback, **ctx.params)
  File "/data/aglinska/anaconda3/lib/python3.8/site-packages/click/core.py", line 610, in invoke
    return callback(*args, **kwargs)
  File "/data/aglinska/anaconda3/lib/python3.8/site-packages/click/decorators.py", line 21, in new_func
    return f(get_current_context(), *args, **kwargs)
  File "/data/aglinska/anaconda3/lib/python3.8/site-packages/papermill/cli.py", line 250, in papermill
    execute_notebook(
  File "/data/aglinska/anaconda3/lib/python3.8/site-packages/papermill/execute.py", line 122, in execute_notebook
    raise_for_execution_errors(nb, output_path)
  File "/data/aglinska/anaconda3/lib/python3.8/site-packages/papermill/execute.py", line 234, in raise_for_execution_errors
    raise error
papermill.exceptions.PapermillExecutionError: 
---------------------------------------------------------------------------
Exception encountered at "In [16]":
---------------------------------------------------------------------------
IndexError                                Traceback (most recent call last)
<ipython-input-16-6b2831697ab1> in <module>
----> 1 sub = subjects[s]
      2 print(sub)
      3 data = get_data(sub)
      4 n = data['epi'].shape[-1]
      5 print(data['epi'].shape)

IndexError: index 191 is out of bounds for axis 0 with size 189

