Input Notebook:  /data/aglinska/BC-fMRI-AE/Notebooks/014-SFARI-compcorr-filter.ipynb
Output Notebook: /data/aglinska/BC-fMRI-AE/Assets/papermill-SFARI-preproc/107-run1-sfari-compcorr.ipynb
Generating grammar tables from /data/aglinska/anaconda3/lib/python3.8/site-packages/blib2to3/Grammar.txt
Writing grammar tables to /data/aglinska/.cache/black/21.8b0/Grammar3.8.5.final.0.pickle
Writing failed: [Errno 2] No such file or directory: '/data/aglinska/.cache/black/21.8b0/tmp7h6p861d'
Generating grammar tables from /data/aglinska/anaconda3/lib/python3.8/site-packages/blib2to3/PatternGrammar.txt
Writing grammar tables to /data/aglinska/.cache/black/21.8b0/PatternGrammar3.8.5.final.0.pickle
Writing failed: [Errno 2] No such file or directory: '/data/aglinska/.cache/black/21.8b0/tmpl08ig253'
Executing:   0%|          | 0/36 [00:00<?, ?cell/s]Executing notebook with kernel: python3
Executing:   3%|▎         | 1/36 [00:04<02:40,  4.57s/cell]Executing:  11%|█         | 4/36 [00:04<01:42,  3.21s/cell]Executing:  14%|█▍        | 5/36 [00:22<03:57,  7.67s/cell]Executing:  22%|██▏       | 8/36 [00:23<02:33,  5.47s/cell]Executing:  31%|███       | 11/36 [00:23<01:35,  3.84s/cell]Executing:  42%|████▏     | 15/36 [00:23<00:56,  2.70s/cell]Executing:  47%|████▋     | 17/36 [00:25<00:40,  2.15s/cell]Executing:  53%|█████▎    | 19/36 [00:25<00:26,  1.54s/cell]Executing:  56%|█████▌    | 20/36 [00:30<00:24,  1.54s/cell]
Traceback (most recent call last):
  File "/data/aglinska/anaconda3/bin/papermill", line 8, in <module>
    sys.exit(papermill())
  File "/data/aglinska/anaconda3/lib/python3.8/site-packages/click/core.py", line 829, in __call__
    return self.main(*args, **kwargs)
  File "/data/aglinska/anaconda3/lib/python3.8/site-packages/click/core.py", line 782, in main
    rv = self.invoke(ctx)
  File "/data/aglinska/anaconda3/lib/python3.8/site-packages/click/core.py", line 1066, in invoke
    return ctx.invoke(self.callback, **ctx.params)
  File "/data/aglinska/anaconda3/lib/python3.8/site-packages/click/core.py", line 610, in invoke
    return callback(*args, **kwargs)
  File "/data/aglinska/anaconda3/lib/python3.8/site-packages/click/decorators.py", line 21, in new_func
    return f(get_current_context(), *args, **kwargs)
  File "/data/aglinska/anaconda3/lib/python3.8/site-packages/papermill/cli.py", line 250, in papermill
    execute_notebook(
  File "/data/aglinska/anaconda3/lib/python3.8/site-packages/papermill/execute.py", line 122, in execute_notebook
    raise_for_execution_errors(nb, output_path)
  File "/data/aglinska/anaconda3/lib/python3.8/site-packages/papermill/execute.py", line 234, in raise_for_execution_errors
    raise error
papermill.exceptions.PapermillExecutionError: 
---------------------------------------------------------------------------
Exception encountered at "In [20]":
---------------------------------------------------------------------------
KeyError                                  Traceback (most recent call last)
<ipython-input-20-49f89985061e> in <module>
      7 scrubbed_nii = make_4depi(mat,data['epi'])
      8 
----> 9 rmat = regress(mat,data['conf'].iloc[~scrub_idx])
     10 
     11 rmat_nii = make_4depi(rmat,data['epi'])

<ipython-input-10-0e66fab4cb49> in regress(flat_epi, conf, idx)
     16 
     17 
---> 18     X = conf[keys].values[idx]
     19     n = X.shape[0]
     20     X = np.hstack((X,np.ones(n)[:,np.newaxis])) # Add mean

~/anaconda3/lib/python3.8/site-packages/pandas/core/frame.py in __getitem__(self, key)
   2906             if is_iterator(key):
   2907                 key = list(key)
-> 2908             indexer = self.loc._get_listlike_indexer(key, axis=1, raise_missing=True)[1]
   2909 
   2910         # take() does not accept boolean indexers

~/anaconda3/lib/python3.8/site-packages/pandas/core/indexing.py in _get_listlike_indexer(self, key, axis, raise_missing)
   1252             keyarr, indexer, new_indexer = ax._reindex_non_unique(keyarr)
   1253 
-> 1254         self._validate_read_indexer(keyarr, indexer, axis, raise_missing=raise_missing)
   1255         return keyarr, indexer
   1256 

~/anaconda3/lib/python3.8/site-packages/pandas/core/indexing.py in _validate_read_indexer(self, key, indexer, axis, raise_missing)
   1302             if raise_missing:
   1303                 not_found = list(set(key) - set(ax))
-> 1304                 raise KeyError(f"{not_found} not in index")
   1305 
   1306             # we skip the warning on Categorical

KeyError: "['a_comp_cor_05'] not in index"

