Input Notebook:  /data/aglinska/BC-fMRI-AE/Notebooks/004-ABIDE-I-and-II-compcorr-filter.ipynb
Output Notebook: /data/aglinska/BC-fMRI-AE/Assets/data_preprocessed_f3_notebooks/03_preprocess_1258.ipynb
Generating grammar tables from /data/aglinska/anaconda3/lib/python3.8/site-packages/blib2to3/Grammar.txt
Writing grammar tables to /data/aglinska/.cache/black/21.8b0/Grammar3.8.5.final.0.pickle
Writing failed: [Errno 2] No such file or directory: '/data/aglinska/.cache/black/21.8b0/tmpjemzq48r'
Generating grammar tables from /data/aglinska/anaconda3/lib/python3.8/site-packages/blib2to3/PatternGrammar.txt
Writing grammar tables to /data/aglinska/.cache/black/21.8b0/PatternGrammar3.8.5.final.0.pickle
Writing failed: [Errno 2] No such file or directory: '/data/aglinska/.cache/black/21.8b0/tmpfh5o_lsq'
Executing:   0%|          | 0/73 [00:00<?, ?cell/s]Executing notebook with kernel: python3
Executing:   1%|▏         | 1/73 [00:05<07:09,  5.97s/cell]Executing:   3%|▎         | 2/73 [00:06<04:58,  4.21s/cell]Executing:   4%|▍         | 3/73 [00:23<09:24,  8.06s/cell]Executing:   5%|▌         | 4/73 [00:23<06:31,  5.67s/cell]Executing:   8%|▊         | 6/73 [00:23<04:27,  3.99s/cell]Executing:  11%|█         | 8/73 [00:23<03:03,  2.82s/cell]Executing:  14%|█▎        | 10/73 [00:23<02:05,  2.00s/cell]Executing:  16%|█▋        | 12/73 [00:23<01:26,  1.42s/cell]Executing:  19%|█▉        | 14/73 [00:28<01:39,  1.68s/cell]Executing:  22%|██▏       | 16/73 [00:28<01:08,  1.20s/cell]Executing:  25%|██▍       | 18/73 [00:28<00:47,  1.17cell/s]Executing:  27%|██▋       | 20/73 [00:28<00:32,  1.62cell/s]Executing:  30%|███       | 22/73 [00:28<00:23,  2.21cell/s]Executing:  33%|███▎      | 24/73 [00:29<00:19,  2.48cell/s]Executing:  36%|███▌      | 26/73 [00:29<00:14,  3.32cell/s]Executing:  38%|███▊      | 28/73 [00:29<00:10,  4.35cell/s]Executing:  41%|████      | 30/73 [00:29<00:07,  5.48cell/s]Executing:  44%|████▍     | 32/73 [00:30<00:06,  6.67cell/s]Executing:  47%|████▋     | 34/73 [00:30<00:05,  6.79cell/s]Executing:  49%|████▉     | 36/73 [00:36<00:39,  1.08s/cell]Executing:  49%|████▉     | 36/73 [00:38<00:39,  1.08s/cell]
Traceback (most recent call last):
  File "/data/aglinska/anaconda3/bin/papermill", line 8, in <module>
    sys.exit(papermill())
  File "/data/aglinska/anaconda3/lib/python3.8/site-packages/click/core.py", line 829, in __call__
    return self.main(*args, **kwargs)
  File "/data/aglinska/anaconda3/lib/python3.8/site-packages/click/core.py", line 782, in main
    rv = self.invoke(ctx)
  File "/data/aglinska/anaconda3/lib/python3.8/site-packages/click/core.py", line 1066, in invoke
    return ctx.invoke(self.callback, **ctx.params)
  File "/data/aglinska/anaconda3/lib/python3.8/site-packages/click/core.py", line 610, in invoke
    return callback(*args, **kwargs)
  File "/data/aglinska/anaconda3/lib/python3.8/site-packages/click/decorators.py", line 21, in new_func
    return f(get_current_context(), *args, **kwargs)
  File "/data/aglinska/anaconda3/lib/python3.8/site-packages/papermill/cli.py", line 250, in papermill
    execute_notebook(
  File "/data/aglinska/anaconda3/lib/python3.8/site-packages/papermill/execute.py", line 122, in execute_notebook
    raise_for_execution_errors(nb, output_path)
  File "/data/aglinska/anaconda3/lib/python3.8/site-packages/papermill/execute.py", line 234, in raise_for_execution_errors
    raise error
papermill.exceptions.PapermillExecutionError: 
---------------------------------------------------------------------------
Exception encountered at "In [23]":
---------------------------------------------------------------------------
KeyError                                  Traceback (most recent call last)
<ipython-input-23-14dc412227e8> in <module>
     10 scrubbed_nii = make_4depi(mat,data['epi'])
     11 
---> 12 rmat = regress(mat,data['conf'].iloc[~scrub_idx])
     13 
     14 rmat_nii = make_4depi(rmat,data['epi'])

<ipython-input-13-92b9476e4852> in regress(flat_epi, conf, idx)
     20 
     21 
---> 22     X = conf[keys].values[idx]
     23     n = X.shape[0]
     24     X = np.hstack((X,np.ones(n)[:,np.newaxis])) # Add mean

~/anaconda3/lib/python3.8/site-packages/pandas/core/frame.py in __getitem__(self, key)
   2906             if is_iterator(key):
   2907                 key = list(key)
-> 2908             indexer = self.loc._get_listlike_indexer(key, axis=1, raise_missing=True)[1]
   2909 
   2910         # take() does not accept boolean indexers

~/anaconda3/lib/python3.8/site-packages/pandas/core/indexing.py in _get_listlike_indexer(self, key, axis, raise_missing)
   1252             keyarr, indexer, new_indexer = ax._reindex_non_unique(keyarr)
   1253 
-> 1254         self._validate_read_indexer(keyarr, indexer, axis, raise_missing=raise_missing)
   1255         return keyarr, indexer
   1256 

~/anaconda3/lib/python3.8/site-packages/pandas/core/indexing.py in _validate_read_indexer(self, key, indexer, axis, raise_missing)
   1302             if raise_missing:
   1303                 not_found = list(set(key) - set(ax))
-> 1304                 raise KeyError(f"{not_found} not in index")
   1305 
   1306             # we skip the warning on Categorical

KeyError: "['a_comp_cor_04'] not in index"

