Input Notebook:  /data/aglinska/BC-fMRI-AE/Notebooks/004-ABIDE-I-and-II-compcorr-filter.ipynb
Output Notebook: /data/aglinska/BC-fMRI-AE/Assets/data_preprocessed_f3_notebooks/03_preprocess_1164.ipynb
Generating grammar tables from /data/aglinska/anaconda3/lib/python3.8/site-packages/blib2to3/Grammar.txt
Writing grammar tables to /data/aglinska/.cache/black/21.8b0/Grammar3.8.5.final.0.pickle
Writing failed: [Errno 2] No such file or directory: '/data/aglinska/.cache/black/21.8b0/tmpdp8uoz4e'
Generating grammar tables from /data/aglinska/anaconda3/lib/python3.8/site-packages/blib2to3/PatternGrammar.txt
Writing grammar tables to /data/aglinska/.cache/black/21.8b0/PatternGrammar3.8.5.final.0.pickle
Writing failed: [Errno 2] No such file or directory: '/data/aglinska/.cache/black/21.8b0/tmpngvk37i1'
Executing:   0%|          | 0/73 [00:00<?, ?cell/s]Executing notebook with kernel: python3
Executing:   1%|▏         | 1/73 [00:02<02:49,  2.35s/cell]Executing:   4%|▍         | 3/73 [00:10<03:16,  2.81s/cell]Executing:   7%|▋         | 5/73 [00:10<02:15,  1.99s/cell]Executing:  10%|▉         | 7/73 [00:10<01:32,  1.41s/cell]Executing:  12%|█▏        | 9/73 [00:10<01:04,  1.00s/cell]Executing:  14%|█▎        | 10/73 [00:13<01:27,  1.39s/cell]
Traceback (most recent call last):
  File "/data/aglinska/anaconda3/bin/papermill", line 8, in <module>
    sys.exit(papermill())
  File "/data/aglinska/anaconda3/lib/python3.8/site-packages/click/core.py", line 829, in __call__
    return self.main(*args, **kwargs)
  File "/data/aglinska/anaconda3/lib/python3.8/site-packages/click/core.py", line 782, in main
    rv = self.invoke(ctx)
  File "/data/aglinska/anaconda3/lib/python3.8/site-packages/click/core.py", line 1066, in invoke
    return ctx.invoke(self.callback, **ctx.params)
  File "/data/aglinska/anaconda3/lib/python3.8/site-packages/click/core.py", line 610, in invoke
    return callback(*args, **kwargs)
  File "/data/aglinska/anaconda3/lib/python3.8/site-packages/click/decorators.py", line 21, in new_func
    return f(get_current_context(), *args, **kwargs)
  File "/data/aglinska/anaconda3/lib/python3.8/site-packages/papermill/cli.py", line 250, in papermill
    execute_notebook(
  File "/data/aglinska/anaconda3/lib/python3.8/site-packages/papermill/execute.py", line 122, in execute_notebook
    raise_for_execution_errors(nb, output_path)
  File "/data/aglinska/anaconda3/lib/python3.8/site-packages/papermill/execute.py", line 234, in raise_for_execution_errors
    raise error
papermill.exceptions.PapermillExecutionError: 
---------------------------------------------------------------------------
Exception encountered at "In [10]":
---------------------------------------------------------------------------
IndexError                                Traceback (most recent call last)
<ipython-input-10-2e51ace2fde8> in <module>
      1 epi_fn = files[[file.endswith('preproc_bold.nii.gz') for file in files]][0]
      2 mask_fn = files[[file.endswith('brain_mask.nii.gz') for file in files]][0]
----> 3 conf_fn = files[[file.endswith('confounds_timeseries.tsv') for file in files]][0]

IndexError: index 0 is out of bounds for axis 0 with size 0

